package Core.exceptionhandling;

class TryFinally {
	public int divide(int a) throws Exception {
		int b = 0;
		try {
			b = 10 / a;
			return b;
		} finally {
			System.out.println("Finally called");
			return 3;
		}
	}

	public static void main(String[] a) {
		try {
			TryFinally obj = new TryFinally();
			int result = obj.divide(0);
			System.out.println("result Main : " + result);
		} catch (Exception e) {
			System.out.println("Divide by Zero 1..... ");
		}
	}
}